<?xml version="1.0" ?>

<robot xmlns:xacro="http://www.ros.org/wiki/xacro">
 <link
    name="Right_Wheel">
    <inertial>
      <origin
        xyz="2.5996E-07 0.037854 6.57E-06"
        rpy="0 0 0" />
      <mass
        value="1.21" />
      <inertia
        ixx="0.0022228"
        ixy="-1.8762E-08"
        ixz="1.5736E-09"
        iyy="0.0036326"
        iyz="-4.7418E-07"
        izz="0.0022228" />
    </inertial>
    <visual>
      <origin
        xyz="0 0 0"
        rpy="0 0 0" />
      <geometry>
        <mesh
          filename="package://waiteronix/meshes/Right_Wheel.STL" />
      </geometry>
      <material
        name="">
        <color
          rgba="0.75294 0.75294 0.75294 1" />
      </material>
    </visual>
    <collision>
      <origin
        xyz="0 0 0"
        rpy="0 0 0" />
      <geometry>
        <mesh
          filename="package://waiteronix/meshes/Right_Wheel.STL" />
      </geometry>
    </collision>
  </link>
  <joint
    name="Right_Wheel_Joint"
    type="continuous">
    <origin
      xyz="0.0087223 0.224 0.038"
      rpy="0 0 0" />
    <parent
      link="base_link" />
    <child
      link="Right_Wheel" />
    <axis
      xyz="0 1 0" />
    <limit
      effort="40"
      velocity="10" />
  </joint>
  <link
    name="Left_Wheel">
    <inertial>
      <origin
        xyz="-2.5996E-07 0.037854 6.57E-06"
        rpy="0 0 0" />
      <mass
        value="1.21" />
      <inertia
        ixx="0.0022228"
        ixy="1.8762E-08"
        ixz="1.5736E-09"
        iyy="0.0036326"
        iyz="4.7418E-07"
        izz="0.0022228" />
    </inertial>
    <visual>
      <origin
        xyz="0 0 0"
        rpy="0 0 0" />
      <geometry>
        <mesh
          filename="package://waiteronix/meshes/Left_Wheel.STL" />
      </geometry>
      <material
        name="">
        <color
          rgba="0.75294 0.75294 0.75294 1" />
      </material>
    </visual>
    <collision>
      <origin
        xyz="0 0 0"
        rpy="0 0 0" />
      <geometry>
        <mesh
          filename="package://waiteronix/meshes/Left_Wheel.STL" />
      </geometry>
    </collision>
  </link>
  <joint
    name="Left_Wheel_Joint"
    type="continuous">
    <origin
      xyz="-0.0087223 0.224 0.038"
      rpy="0 0 0" />
    <parent
      link="base_link" />
    <child
      link="Left_Wheel" />
    <axis
      xyz="0 1 0" />
    <limit
      effort="40"
      velocity="10" />
  </joint>
</robot>