<?xml version="1.0" encoding="utf-8"?>
<!-- This URDF was automatically created by SolidWorks to URDF Exporter! Originally created by Stephen Brawner (brawner@gmail.com) 
     Commit Version: 1.6.0-4-g7f85cfe  Build Version: 1.6.7995.38578
     For more information, please see http://wiki.ros.org/sw_urdf_exporter -->
<robot
  name="Waiteronix" xmlns:xacro="http://www.ros.org/wiki/xacro">
  <xacro:include filename="$(find Waiteronix)/urdf/waiteronix.gazebo"/>
   <link name="robot_footprint">
  </link>
  <link
    name="Main_link">
    <inertial>
      <origin
        xyz="0.046544 2.0111E-05 0.18108"
        rpy="0 0 0" />
      <mass
        value="13.271" />
      <inertia
        ixx="0.2687"
        ixy="1.6622E-07"
        ixz="-0.014269"
        iyy="0.30311"
        iyz="-4.5028E-07"
        izz="0.3463" />
    </inertial>
    <visual>
      <origin
        xyz="0 0 0"
        rpy="0 0 0" />
      <geometry>
        <mesh
          filename="package://Waiteronix/meshes/Main_link.STL" />
      </geometry>
      <material
        name="">
        <color
          rgba="0.77647 0.75686 0.73725 1" />
      </material>
    </visual>
    <collision>
      <origin
        xyz="0 0 0"
        rpy="0 0 0" />
      <geometry>
        <mesh
          filename="package://Waiteronix/meshes/Main_link.STL" />
      </geometry>
    </collision>
  </link>
  <link
    name="left_wheel_Link">
    <inertial>
      <origin
        xyz="-3.4694E-18 -0.037433 3.1919E-16"
        rpy="0 0 0" />
      <mass
        value="1.1947" />
      <inertia
        ixx="0.0021952"
        ixy="-1.2945E-19"
        ixz="-2.3445E-19"
        iyy="0.0036631"
        iyz="-1.2209E-17"
        izz="0.0021952" />
    </inertial>
    <visual>
      <origin
        xyz="0 0 0"
        rpy="0 0 0" />
      <geometry>
        <mesh
          filename="package://Waiteronix/meshes/left_wheel_Link.STL" />
      </geometry>
      <material
        name="">
        <color
          rgba="0.79216 0.81961 0.93333 1" />
      </material>
    </visual>
    <collision>
      <origin
        xyz="0 0 0"
        rpy="0 0 0" />
      <geometry>
        <mesh
          filename="package://Waiteronix/meshes/left_wheel_Link.STL" />
      </geometry>
    </collision>
  </link>
    <joint name="dummy_joint" type="fixed">
    <parent link="robot_footprint"/>
    <child link="Main_link"/>
   </joint>
  <joint
    name="left_wheel_joint"
    type="continuous">
    <origin
      xyz="-0.0087223 0.224 0.04395"
      rpy="0 0 0" />
    <parent
      link="Main_link" />
    <child
      link="left_wheel_Link" />
    <axis
      xyz="0 -1 0" />
    <limit
      effort="2"
      velocity="1" />
  </joint>
  <link
    name="right_wheel_Link">
    <inertial>
      <origin
        xyz="-6.5919E-17 0.037433 -3.2613E-16"
        rpy="0 0 0" />
      <mass
        value="1.1947" />
      <inertia
        ixx="0.0021952"
        ixy="6.4163E-19"
        ixz="4.8195E-20"
        iyy="0.0036631"
        iyz="-1.2587E-17"
        izz="0.0021952" />
    </inertial>
    <visual>
      <origin
        xyz="0 0 0"
        rpy="0 0 0" />
      <geometry>
        <mesh
          filename="package://Waiteronix/meshes/right_wheel_Link.STL" />
      </geometry>
      <material
        name="">
        <color
          rgba="0.79216 0.81961 0.93333 1" />
      </material>
    </visual>
    <collision>
      <origin
        xyz="0 0 0"
        rpy="0 0 0" />
      <geometry>
        <mesh
          filename="package://Waiteronix/meshes/right_wheel_Link.STL" />
      </geometry>
    </collision>
  </link>
  <joint
    name="right_wheel_joint"
    type="continuous">
    <origin
      xyz="-0.0087223 -0.224 0.04395"
      rpy="0 0 0" />
    <parent
      link="Main_link" />
    <child
      link="right_wheel_Link" />
    <axis
      xyz="0 -1 0" />
    <limit
      effort="2"
      velocity="1" />
  </joint>
  <link
    name="lidar_Link">
    <inertial>
      <origin
        xyz="-0.0042466 2.7248E-12 -0.040019"
        rpy="0 0 0" />
      <mass
        value="0.24913" />
      <inertia
        ixx="0.00016349"
        ixy="-4.1601E-21"
        ixz="1.0298E-19"
        iyy="0.00016389"
        iyz="4.874E-23"
        izz="0.0001528" />
    </inertial>
    <visual>
      <origin
        xyz="0 0 0"
        rpy="0 0 0" />
      <geometry>
        <mesh
          filename="package://Waiteronix/meshes/lidar_Link.STL" />
      </geometry>
      <material
        name="">
        <color
          rgba="0 0.75294 0 1" />
      </material>
    </visual>
    <collision>
      <origin
        xyz="0 0 0"
        rpy="0 0 0" />
      <geometry>
        <mesh
          filename="package://Waiteronix/meshes/lidar_Link.STL" />
      </geometry>
    </collision>
  </link>
  <joint
    name="lidar_goint"
    type="fixed">
    <origin
      xyz="0.185 0 0.20663"
      rpy="0 0 0" />
    <parent
      link="Main_link" />
    <child
      link="lidar_Link" />
    <axis
      xyz="0 0 0" />
  </joint>
  <link
    name="IMU_Link">
    <inertial>
      <origin
        xyz="-1.3276E-17 2.8137E-17 -0.005"
        rpy="0 0 0" />
      <mass
        value="0.0007854" />
      <inertia
        ixx="1.1454E-08"
        ixy="-2.5419E-25"
        ixz="-3.7851E-24"
        iyy="1.1454E-08"
        iyz="9.2892E-24"
        izz="9.8175E-09" />
    </inertial>
    <visual>
      <origin
        xyz="0 0 0"
        rpy="0 0 0" />
      <geometry>
        <mesh
          filename="package://Waiteronix/meshes/IMU_Link.STL" />
      </geometry>
      <material
        name="">
        <color
          rgba="0 0.75294 0 1" />
      </material>
    </visual>
    <collision>
      <origin
        xyz="0 0 0"
        rpy="0 0 0" />
      <geometry>
        <mesh
          filename="package://Waiteronix/meshes/IMU_Link.STL" />
      </geometry>
    </collision>
  </link>
  <joint
    name="IMU_joint"
    type="fixed">
    <origin
      xyz="0 0 0.289"
      rpy="0 0 0" />
    <parent
      link="Main_link" />
    <child
      link="IMU_Link" />
    <axis
      xyz="0 0 0" />
  </joint>
  <link
    name="camera_Link">
    <inertial>
      <origin
        xyz="0 0 0"
        rpy="0 0 0" />
      <mass
        value="0.5" />
      <inertia
        ixx="0"
        ixy="0"
        ixz="0"
        iyy="0"
        iyz="0"
        izz="0" />
    </inertial>
    <visual>
      <origin
        xyz="0 0 0"
        rpy="0 0 0" />
      <geometry>
        <mesh
          filename="package://Waiteronix/meshes/camera_Link.STL" />
      </geometry>
      <material
        name="">
        <color
          rgba="1 1 1 1" />
      </material>
    </visual>
    <collision>
      <origin
        xyz="0 0 0"
        rpy="0 0 0" />
      <geometry>
        <mesh
          filename="package://Waiteronix/meshes/camera_Link.STL" />
      </geometry>
    </collision>
  </link>
  <joint
    name="camera_joint"
    type="fixed">
    <origin
      xyz="0.25169 -0.026307 0.99432"
      rpy="0 0.34907 0" />
    <parent
      link="Main_link" />
    <child
      link="camera_Link" />
    <axis
      xyz="0 0 0" />
  </joint>
</robot>